<!DOCTYPE html>
<html lang="en">

<head>
    <meta charset="UTF-8">
    <meta name="viewport" content="width=device-width, initial-scale=1.0">
    <title>async</title>
</head>

<body>
    <script>
        function timeout(ms) {
            return new Promise((resolve, reject) => {
                setTimeout(() => {
                    if (ms === 1000) {
                        reject(ms)
                    }
                    resolve(ms)
                }, ms)
            })
        }
        async function asyncPrint() {
            let ret1 = await timeout(1000);
            // console.log('ret1', ret1)
            let ret2 = await timeout(2000);
            // console.log('ret2', ret2)
        }
        let s = asyncPrint();
        // 如果async函数里面抛出了错误的话，函数体内下面的语句就不会再执行了，返回的promise实例也是reject态的；
        s.catch((err) => {
                // console.log("接收到错误：", err)
            })
            // async函数返回的也是promise，所以在别的函数里也可以使用await使用
        async function timeout2(ms) {
            return await new Promise((resolve, reject) => {
                setTimeout(() => {
                    resolve(ms)
                }, ms)
            })
        }
        async function asyncPrint2() {
            let ret1 = await timeout2(1000);
            // console.log('asyncPrint2---ret1', ret1)
            let ret2 = await timeout2(2000);
            // console.log('asyncPrint2---ret2', ret2)
        }
        asyncPrint2().then('_', (err) => {
            // console.log("在then的第二个回调参数里面获得错误", err)
        });
        // return
        function timeout3(ms) {
            return new Promise((resolve, reject) => {
                setTimeout(() => {
                    resolve(ms)
                }, ms)
            })
        }
        async function asyncPrint3() {
            let ret1 = await timeout3(1000);
            // console.log('asyncPrint3---ret1', ret1);
            return 'return中途返回值'
            let ret2 = await timeout(2000);
            // console.log('asyncPrint3---ret2', ret2);
        }
        asyncPrint3().then((value) => {
            // console.log("async-return返回：", value)
        });
        /* async函数返回的 Promise 对象，必须等到内部所有await命令后面的 Promise 对象执行完，才会发生状态改变，
         *除非遇到return语句或者抛出错误。也就是说，只有async函数内部的异步操作执行完，才会执行then方法指定的回调函数。
         */
        // await后面不是promise实例，是其他值， 内部会直接调用Promise.reaolve(这个常量值);
        async function fn() {
            return await 123;
        }
        fn().then((v) => {
                // console.log(v);
            })
            // await 后面是个带有then方法的对象, 浏览器会将其作为promise对象处理。
        class Sleep {
            constructor(ms) {
                this.timeout = ms;
            }
            then(resolve, reject) {
                let startTime = Date.now();
                setTimeout(
                    function() {
                        resolve(Date.now() - startTime);
                    }, this.timeout)
            }
        }
        (async() => {
            let sleepTime = await new Sleep(1000);
            // console.log('await后面是带有then方法的对象', sleepTime);
        })()
        //* await命令后面的 Promise 对象如果变为reject状态，则reject的参数会被catch方法的回调函数接收到。
        let async4 = (async() => {
            try {
                let ret1 = await Promise.reject('第一个出错了');
                // console.log('async4-ret1', ret1)
            } catch (error) {
                // console.log('try-catch-async4', error)
            }

            let ret2 = await Promise.reject('第二个出错了');
            // console.log('async4-ret2', ret2)
        })();
        async4.then((value) => {
                // console.log('async4-then结果', value)
            }).catch((err) => {
                // console.log('async4-catch结果', err)
            })
            //* 防止出错的办法：使用 try catch 包裹 
        function timeout5(ms) {
            return new Promise((resolve, reject) => {
                setTimeout(() => {
                    // if()
                    reject(ms)
                }, ms)
            })
        }
        //如果将多个await包裹在一个trycatch中，其中一个出错了后面的也是不会执行，最好的办法就是将其分别放在try catch里面。
        async function asyncPrint5() {
            try {
                let ret1 = await timeout5(100)
                    // console.log("asyncPrint5-ret1", ret1)
            } catch (error) {
                // console.log("asyncPrint5-err1", error);
            }
            try {

                let ret2 = await timeout5(200)
                    // console.log("asyncPrint5-ret2", ret2)
            } catch (error) {
                // console.log("asyncPrint5-err2", error);
            }
            try {
                let ret3 = await timeout5(300)
                    // console.log("asyncPrint5-ret3", ret3)
            } catch (error) {
                // console.log("asyncPrint5-err3", error);
            }
            return 111
        }
        let s5 = asyncPrint5();
        s5.then((value) => {
                // console.log('asyncPrint5-then', value)
            })
            // 多次重复尝试请求一个接口，知道返回成功或达到最大的请求次数
        function timeout6() {
            return new Promise((resolve, reject) => {
                let ran = Math.random()
                ran > 0.5 ? resolve(ran) : reject(ran);
            })
        }
        async function asyncPrint6() {
            let MAX = 3;
            for (let i = 0; i < MAX; i++) {
                try {
                    let ret = await timeout6();
                    // console.log(`第${i+1}次成功`)
                    break;
                } catch (error) {
                    // console.log("asyncPrint6-出错")
                }
            }
        }
        asyncPrint6();
        //* 多个await的继发关系
        //* 放在循环中 forEach据说会有问题， 建议放在for循环中
        ([{}, {}, {}]).forEach(async(ele) => {
            console.log(await ele);
        });
        //* 并发请求使用Promise.all();
        //* async 可以保留执行栈 

        //! 几种异步处理方法的比较
        // 给一个DOM元素部署一系列的动画， 要求动画必需一个执行完才能执行另一个
        // ①Promise
        function resolveAnimations(ele, animations) {
            let p = Promise.resolve();
            let ret = null;
            // p.then.then.then.then.then....
            for (let i = 0; i < animations.length; i++) {
                p = p.then(function(val) {
                    ret = val;
                    return animations[i](ele);
                })
            }
            return p.catch((err) => {}).then(() => {
                return ret;
            })
        }
        // ②async
        function resolveAnimations2(ele, animations) {
            let ret = null;
            try {
                for (let i = 0; i < animations.length; i++) {
                    ret = await animations[i](ele)
                }
            } catch (error) {
                // ...
            }
            return ret;
        }
        //! 书序读取一串urls服务器的内容, 依次输出结果
        // ① Promise
        function reqUrls(urls) {
            let Promises = urls.map((url) => {
                return fetch(url).then(reponse => reponse.text())
            })
            Promises.reduce((chain, pro) => {
                chain.then(() => {
                    return pro;
                }).then((ret) => {
                    console.log(ret)
                })
            }, Promise.resolve())
        }
        //② async
        function reqUrls2(urls) {

            for (let url of urls) {
                let response = await fetch(url);
                console.log(response);
            }
        }
        // 但是上面的方法每个请求还是继发的，下面改造成并发的
        function reqUrls3(urls) {
            let Promises = urls.map(async(url) => {
                let reponse = fetch(url);
                return reponse.text()
            })
            for (let pro of Promises) {
                console.log(await pro);
            }
        }
    </script>
</body>

</html>